<?xml version="1.0" ?>
<!-- =================================================================================== -->
<!-- |    This document was autogenerated by xacro from src/hive_robot_description/model/mk5_200.urdf.xacro | -->
<!-- |    EDITING THIS FILE BY HAND IS NOT RECOMMENDED                                 | -->
<!-- =================================================================================== -->
<robot name="robot1">
  <!-- ========= MATÉRIAUX ========= -->
  <material name="robot1_black">
    <color rgba="0 0 0 1"/>
  </material>
  <material name="robot1_grey">
    <color rgba="0.5 0.5 0.5 1"/>
  </material>
  <material name="robot1_red">
    <color rgba="1 0 0 1"/>
  </material>
  <material name="robot1_bleu">
    <color rgba="0 0 1 1"/>
  </material>
  <material name="robot1_jaune">
    <color rgba="1 1 0 1"/>
  </material>
  <!-- ========= FOOTPRINT ========= -->
  <link name="robot1_base_footprint"/>
  <!-- ========= BASE LINK ========= -->
  <link name="robot1_base_link">
    <visual>
      <geometry>
        <box size="0.2 0.4 0.15"/>
      </geometry>
      <origin xyz="-0.025 0 0"/>
      <material name="robot1_bleu"/>
    </visual>
    <collision>
      <geometry>
        <box size="0.2 0.4 0.15"/>
      </geometry>
      <origin xyz="-0.025 0 0"/>
    </collision>
    <inertial>
      <mass value="50.0"/>
      <origin xyz="-0.2 0 0.1"/>
      <inertia ixx="0.76" ixy="0" ixz="0" iyy="0.26" iyz="0" izz="0.833"/>
    </inertial>
    <!-- Grande plaque -->
    <visual>
      <geometry>
        <box size="0.7 0.8 0.02"/>
      </geometry>
      <origin xyz="-0.5 0 0.12300000000000001"/>
      <material name="robot1_bleu"/>
    </visual>
    <collision>
      <geometry>
        <box size="0.7 0.8 0.02"/>
      </geometry>
      <origin xyz="-0.5 0 0.12300000000000001"/>
    </collision>
    <!-- Boite -->
    <visual>
      <geometry>
        <box size="0.8 0.8 0.7"/>
      </geometry>
      <origin xyz="-0.55 0 0.5"/>
      <material name="robot1_grey"/>
    </visual>
    <collision>
      <geometry>
        <box size="0.8 0.8 0.7"/>
      </geometry>
      <origin xyz="-0.55 0 0.5"/>
    </collision>
    <!-- Plaque avant -->
    <visual>
      <geometry>
        <box size="0.9 0.4 0.04999999999999999"/>
      </geometry>
      <origin rpy="0 1.4 0" xyz="-0.05 0 0.5"/>
      <material name="robot1_bleu"/>
    </visual>
    <collision>
      <geometry>
        <box size="0.9 0.4 0.04999999999999999"/>
      </geometry>
      <origin rpy="0 1.4 0" xyz="-0.05 0 0.5"/>
    </collision>
  </link>
  <joint name="robot1_base_link_joint" type="fixed">
    <parent link="robot1_base_footprint"/>
    <child link="robot1_base_link"/>
    <origin xyz="0 0 0.162"/>
  </joint>
  <link name="robot1_left_wheel_link">
    <visual>
      <geometry>
        <cylinder length="0.15" radius="0.162"/>
      </geometry>
      <origin rpy="1.570796 0 0" xyz="0 0 0"/>
      <material name="robot1_black"/>
    </visual>
    <collision>
      <geometry>
        <cylinder length="0.15" radius="0.162"/>
      </geometry>
      <origin rpy="1.570796 0 0" xyz="0 0 0"/>
      <surface>
        <friction>
          <ode>
            <mu>1.0</mu>
            <mu2>1.0</mu2>
          </ode>
        </friction>
      </surface>
    </collision>
    <inertial>
      <mass value="8.0"/>
      <origin xyz="0 0 0"/>
      <inertia ixx="0.1" ixy="0.0" ixz="0.0" iyy="0.06" iyz="0.0" izz="0.06"/>
    </inertial>
  </link>
  <joint name="robot1_left_wheel_joint" type="continuous">
    <parent link="robot1_base_link"/>
    <child link="robot1_left_wheel_link"/>
    <origin xyz="0 0.317 0"/>
    <axis xyz="0 1 0"/>
    <limit effort="50000" velocity="10"/>
    <dynamics damping="1.0" friction="1.0"/>
  </joint>
  <link name="robot1_right_wheel_link">
    <visual>
      <geometry>
        <cylinder length="0.15" radius="0.162"/>
      </geometry>
      <origin rpy="1.570796 0 0" xyz="0 0 0"/>
      <material name="robot1_black"/>
    </visual>
    <collision>
      <geometry>
        <cylinder length="0.15" radius="0.162"/>
      </geometry>
      <origin rpy="1.570796 0 0" xyz="0 0 0"/>
      <surface>
        <friction>
          <ode>
            <mu>1.0</mu>
            <mu2>1.0</mu2>
          </ode>
        </friction>
      </surface>
    </collision>
    <inertial>
      <mass value="8.0"/>
      <origin xyz="0 0 0"/>
      <inertia ixx="0.1" ixy="0.0" ixz="0.0" iyy="0.06" iyz="0.0" izz="0.06"/>
    </inertial>
  </link>
  <joint name="robot1_right_wheel_joint" type="continuous">
    <parent link="robot1_base_link"/>
    <child link="robot1_right_wheel_link"/>
    <origin xyz="0 -0.317 0"/>
    <axis xyz="0 1 0"/>
    <limit effort="50000" velocity="10"/>
    <dynamics damping="1.0" friction="1.0"/>
  </joint>
  <link name="robot1_left_caster_plate_link">
    <visual>
      <geometry>
        <box size="0.18 0.18 0.01"/>
      </geometry>
      <material name="robot1_grey"/>
    </visual>
    <collision>
      <geometry>
        <box size="0.18 0.18 0.01"/>
      </geometry>
    </collision>
    <inertial>
      <mass value="0.5"/>
      <origin xyz="0 0 0"/>
      <inertia ixx="0.001" ixy="0.0" ixz="0.0" iyy="0.001" iyz="0.0" izz="0.002"/>
    </inertial>
  </link>
  <joint name="robot1_left_caster_plate_joint" type="continuous">
    <parent link="robot1_base_link"/>
    <child link="robot1_left_caster_plate_link"/>
    <origin xyz="-0.747 0.26 0.10300000000000001"/>
    <axis xyz="0 0 1"/>
  </joint>
  <!-- petite roue -->
  <link name="robot1_left_caster_wheel_link">
    <visual>
      <geometry>
        <cylinder length="0.08" radius="0.13"/>
      </geometry>
      <origin rpy="1.570796 0 0" xyz="0 0 0"/>
      <material name="robot1_black"/>
    </visual>
    <collision>
      <geometry>
        <cylinder length="0.08" radius="0.13"/>
      </geometry>
      <origin rpy="1.570796 0 0" xyz="0 0 0"/>
    </collision>
    <inertial>
      <mass value="1.0"/>
      <origin xyz="0 0 0"/>
      <inertia ixx="0.0037" ixy="0.0" ixz="0.0" iyy="0.0037" iyz="0.0" izz="0.0010"/>
    </inertial>
  </link>
  <joint name="robot1_left_caster_wheel_joint" type="continuous">
    <parent link="robot1_left_caster_plate_link"/>
    <child link="robot1_left_caster_wheel_link"/>
    <origin xyz="-0.06 0 -0.13"/>
    <axis xyz="0 1 0"/>
  </joint>
  <link name="robot1_right_caster_plate_link">
    <visual>
      <geometry>
        <box size="0.18 0.18 0.01"/>
      </geometry>
      <material name="robot1_grey"/>
    </visual>
    <collision>
      <geometry>
        <box size="0.18 0.18 0.01"/>
      </geometry>
    </collision>
    <inertial>
      <mass value="0.5"/>
      <origin xyz="0 0 0"/>
      <inertia ixx="0.001" ixy="0.0" ixz="0.0" iyy="0.001" iyz="0.0" izz="0.002"/>
    </inertial>
  </link>
  <joint name="robot1_right_caster_plate_joint" type="continuous">
    <parent link="robot1_base_link"/>
    <child link="robot1_right_caster_plate_link"/>
    <origin xyz="-0.747 -0.26 0.10300000000000001"/>
    <axis xyz="0 0 1"/>
  </joint>
  <!-- petite roue -->
  <link name="robot1_right_caster_wheel_link">
    <visual>
      <geometry>
        <cylinder length="0.08" radius="0.13"/>
      </geometry>
      <origin rpy="1.570796 0 0" xyz="0 0 0"/>
      <material name="robot1_black"/>
    </visual>
    <collision>
      <geometry>
        <cylinder length="0.08" radius="0.13"/>
      </geometry>
      <origin rpy="1.570796 0 0" xyz="0 0 0"/>
    </collision>
    <inertial>
      <mass value="1.0"/>
      <origin xyz="0 0 0"/>
      <inertia ixx="0.0037" ixy="0.0" ixz="0.0" iyy="0.0037" iyz="0.0" izz="0.0010"/>
    </inertial>
  </link>
  <joint name="robot1_right_caster_wheel_joint" type="continuous">
    <parent link="robot1_right_caster_plate_link"/>
    <child link="robot1_right_caster_wheel_link"/>
    <origin xyz="-0.06 0 -0.13"/>
    <axis xyz="0 1 0"/>
  </joint>
  <link name="robot1_airy_front_link">
    <visual>
      <geometry>
        <cylinder length="0.06" radius="0.04"/>
      </geometry>
      <material name="robot1_red"/>
    </visual>
    <collision>
      <geometry>
        <cylinder length="0.06" radius="0.04"/>
      </geometry>
    </collision>
    <inertial>
      <mass value="0.2"/>
      <origin xyz="0 0 0"/>
      <inertia ixx="0.0002" ixy="0.0" ixz="0.0" iyy="0.0002" iyz="0.0" izz="0.0002"/>
    </inertial>
  </link>
  <joint name="robot1_airy_front_joint" type="fixed">
    <parent link="robot1_base_link"/>
    <child link="robot1_airy_front_link"/>
    <origin rpy="0 2.0 0" xyz="0.05 0.0 0.8"/>
  </joint>
  <link name="robot1_jt16_center_link">
    <visual>
      <geometry>
        <cylinder length="0.06" radius="0.04"/>
      </geometry>
      <material name="robot1_red"/>
    </visual>
    <collision>
      <geometry>
        <cylinder length="0.06" radius="0.04"/>
      </geometry>
    </collision>
    <inertial>
      <mass value="0.2"/>
      <origin xyz="0 0 0"/>
      <inertia ixx="0.0002" ixy="0.0" ixz="0.0" iyy="0.0002" iyz="0.0" izz="0.0002"/>
    </inertial>
  </link>
  <joint name="robot1_jt16_center_joint" type="fixed">
    <parent link="robot1_base_link"/>
    <child link="robot1_jt16_center_link"/>
    <origin rpy="0 3.14 0" xyz="-0.607 0.0 0.025"/>
  </joint>
  <link name="robot1_airy_back_link">
    <visual>
      <geometry>
        <cylinder length="0.06" radius="0.04"/>
      </geometry>
      <material name="robot1_red"/>
    </visual>
    <collision>
      <geometry>
        <cylinder length="0.06" radius="0.04"/>
      </geometry>
    </collision>
    <inertial>
      <mass value="0.2"/>
      <origin xyz="0 0 0"/>
      <inertia ixx="0.0002" ixy="0.0" ixz="0.0" iyy="0.0002" iyz="0.0" izz="0.0002"/>
    </inertial>
  </link>
  <joint name="robot1_airy_back_joint" type="fixed">
    <parent link="robot1_base_link"/>
    <child link="robot1_airy_back_link"/>
    <origin rpy="0 -1.57 0" xyz="-0.87 0.0 0.085"/>
  </joint>
  <!-- ======= FRICTION (au sol/roues/roulettes) ======= -->
  <gazebo reference="robot1_base_link">
    <mu1>0.2</mu1>
    <mu2>0.2</mu2>
  </gazebo>
  <gazebo reference="robot1_left_wheel_link">
    <mu1>0.9</mu1>
    <mu2>0.9</mu2>
  </gazebo>
  <gazebo reference="robot1_right_wheel_link">
    <mu1>0.9</mu1>
    <mu2>0.9</mu2>
  </gazebo>
  <gazebo reference="robot1_left_caster_plate_link">
    <mu1>0.2</mu1>
    <mu2>0.2</mu2>
  </gazebo>
  <gazebo reference="robot1_right_caster_plate_link">
    <mu1>0.2</mu1>
    <mu2>0.2</mu2>
  </gazebo>
  <gazebo reference="robot1_left_caster_wheel_link">
    <mu1>0.9</mu1>
    <mu2>0.9</mu2>
  </gazebo>
  <gazebo reference="robot1_right_caster_wheel_link">
    <mu1>0.9</mu1>
    <mu2>0.9</mu2>
  </gazebo>
  <!-- ======= LIDAR AVANT ======= -->
  <gazebo reference="robot1_airy_front_link">
    <sensor name="robot1_gpu_lidar3d_airy_front" type="gpu_lidar">
      <pose relative_to="robot1_airy_front_link">0 0 0 0 0 0</pose>
      <!-- TOPIC ABSOLU (unique multi-robot) -->
      <topic>/robot1/airy_front_pc2</topic>
      <update_rate>10</update_rate>
      <lidar>
        <scan>
          <horizontal>
            <samples>360</samples>
            <resolution>1</resolution>
            <min_angle>-3.1416</min_angle>
            <max_angle>3.1416</max_angle>
          </horizontal>
          <vertical>
            <samples>32</samples>
            <resolution>1</resolution>
            <min_angle>0.0</min_angle>
            <max_angle>1.5708</max_angle>
          </vertical>
        </scan>
        <range>
          <min>0.1</min>
          <max>30.0</max>
          <resolution>0.01</resolution>
        </range>
        <noise type="gaussian">
          <mean>0.0</mean>
          <stddev>0.01</stddev>
        </noise>
      </lidar>
      <always_on>1</always_on>
      <visualize>1</visualize>
    </sensor>
  </gazebo>
  <!-- ======= LIDAR CENTRAL ======= -->
  <gazebo reference="robot1_jt16_center_link">
    <sensor name="robot1_gpu_lidar3d_jt16_center" type="gpu_lidar">
      <pose relative_to="robot1_jt16_center_link">0 0 0 0 0 0</pose>
      <!-- TOPIC ABSOLU (unique multi-robot) -->
      <topic>/robot1/jt16_center_pc2</topic>
      <update_rate>10</update_rate>
      <lidar>
        <scan>
          <horizontal>
            <samples>360</samples>
            <resolution>1</resolution>
            <min_angle>-3.24</min_angle>
            <max_angle>3.24</max_angle>
          </horizontal>
          <vertical>
            <samples>32</samples>
            <resolution>1</resolution>
            <min_angle>0.0</min_angle>
            <max_angle>0.6981</max_angle>
          </vertical>
        </scan>
        <range>
          <min>0.1</min>
          <max>30.0</max>
          <resolution>0.01</resolution>
        </range>
        <noise type="gaussian">
          <mean>0.0</mean>
          <stddev>0.01</stddev>
        </noise>
      </lidar>
      <always_on>1</always_on>
      <visualize>1</visualize>
    </sensor>
  </gazebo>
  <!-- ======= LIDAR ARRIÈRE ======= -->
  <gazebo reference="robot1_airy_back_link">
    <sensor name="robot1_gpu_lidar3d_airy_back" type="gpu_lidar">
      <pose relative_to="robot1_airy_back_link">0 0 0 0 0 0</pose>
      <!-- TOPIC ABSOLU (unique multi-robot) -->
      <topic>/robot1/airy_back_pc2</topic>
      <update_rate>10</update_rate>
      <lidar>
        <scan>
          <horizontal>
            <samples>360</samples>
            <resolution>1</resolution>
            <min_angle>-3.24</min_angle>
            <max_angle>3.24</max_angle>
          </horizontal>
          <vertical>
            <samples>32</samples>
            <resolution>1</resolution>
            <min_angle>0.0</min_angle>
            <max_angle>1.5708</max_angle>
          </vertical>
        </scan>
        <range>
          <min>0.1</min>
          <max>30.0</max>
          <resolution>0.01</resolution>
        </range>
        <noise type="gaussian">
          <mean>0.0</mean>
          <stddev>0.01</stddev>
        </noise>
      </lidar>
      <always_on>1</always_on>
      <visualize>1</visualize>
    </sensor>
  </gazebo>
  <!-- ======= Plugins globaux GAZEBO ======= -->
  <gazebo>
    <plugin filename="gz-sim-diff-drive-system" name="gz::sim::v8::systems::DiffDrive">
      <wheel_separation>0.634</wheel_separation>
      <wheel_radius>0.162</wheel_radius>
      <left_joint>robot1_left_wheel_joint</left_joint>
      <right_joint>robot1_right_wheel_joint</right_joint>
      <max_linear_acceleration>10</max_linear_acceleration>
      <!-- Topic ABSOLU multi-robot ! -->
      <topic>/robot1/cmd_vel</topic>
      <tf_topic>/robot1/tf</tf_topic>
      <odom_topic>/robot1/odom</odom_topic>
      <frame_id>robot1/odom</frame_id>
      <child_frame_id>robot1/base_footprint</child_frame_id>
      <odom_publisher_frequency>30</odom_publisher_frequency>
    </plugin>
    <plugin filename="gz-sim-joint-state-publisher-system" name="gz::sim::systems::JointStatePublisher">
      <topic>/robot1/joint_states</topic>
      <joint_name>robot1_left_wheel_joint</joint_name>
      <joint_name>robot1_right_wheel_joint</joint_name>
    </plugin>
  </gazebo>
</robot>
