<?xml version="1.0" ?>
<!-- =================================================================================== -->
<!-- |    This document was autogenerated by xacro from /home/thomas24/hiveverse_ws/src/hive_robot_description/urdf/mk5_200.urdf.xacro | -->
<!-- |    EDITING THIS FILE BY HAND IS NOT RECOMMENDED                                 | -->
<!-- =================================================================================== -->
<robot name="mk5-200">
  <!-- Plugin natif Gazebo Sim DiffDrive -->
  <plugin filename="libgz-sim8-diff-drive-system.so" name="gz::sim::systems::DiffDrive">
    <left_joint>left_wheel_joint</left_joint>
    <right_joint>right_wheel_joint</right_joint>
    <wheel_separation>0.634</wheel_separation>
    <wheel_radius>0.162</wheel_radius>
    <topic>cmd_vel</topic>
    <odom_publish_frequency>30</odom_publish_frequency>
  </plugin>
  <!-- ========= MATÉRIAUX ========= -->
  <material name="black">
    <color rgba="0 0 0 1"/>
  </material>
  <material name="grey">
    <color rgba="0.5 0.5 0.5 1"/>
  </material>
  <material name="red">
    <color rgba="1 0 0 1"/>
  </material>
  <material name="bleu">
    <color rgba="0 0 1 1"/>
  </material>
  <material name="jaune">
    <color rgba="1 1 0 1"/>
  </material>
  <!-- ========= FOOTPRINT ========= -->
  <link name="base_footprint"/>
  <!-- ========= BASE BLOCK ========= -->
  <link name="base_block">
    <visual>
      <geometry>
        <box size="0.2 0.4 0.15"/>
      </geometry>
      <origin xyz="-0.025 0 0"/>
      <material name="bleu"/>
    </visual>
    <collision>
      <geometry>
        <box size="0.2 0.4 0.15"/>
      </geometry>
      <origin xyz="-0.025 0 0"/>
    </collision>
    <inertial>
      <mass value="13.0"/>
      <origin xyz="0 0 0"/>
      <inertia ixx="0.03" ixy="0" ixz="0" iyy="0.03" iyz="0" izz="0.03"/>
    </inertial>
  </link>
  <joint name="base_block_joint" type="fixed">
    <parent link="base_footprint"/>
    <child link="base_block"/>
    <origin xyz="0 0 0.162"/>
  </joint>
  <!-- ========= GRANDE PLAQUE ========= -->
  <link name="base_plate">
    <visual>
      <geometry>
        <box size="0.7 0.8 0.02"/>
      </geometry>
      <origin xyz="-0.5 0 0.12300000000000001"/>
      <material name="bleu"/>
    </visual>
    <collision>
      <geometry>
        <box size="0.7 0.8 0.02"/>
      </geometry>
      <origin xyz="-0.5 0 0.12300000000000001"/>
    </collision>
    <inertial>
      <mass value="13.0"/>
      <origin xyz="0 0 0"/>
      <inertia ixx="0.03" ixy="0" ixz="0" iyy="0.03" iyz="0" izz="0.03"/>
    </inertial>
  </link>
  <joint name="base_plate_joint" type="fixed">
    <parent link="base_block"/>
    <child link="base_plate"/>
    <origin xyz="0 0 0"/>
  </joint>
  <!-- ========= BOITE ========= -->
  <link name="base_box">
    <visual>
      <geometry>
        <box size="0.8 0.8 0.7"/>
      </geometry>
      <origin xyz="-0.55 0 0.5"/>
      <material name="grey"/>
    </visual>
    <collision>
      <geometry>
        <box size="0.8 0.8 0.7"/>
      </geometry>
      <origin xyz="-0.55 0 0.5"/>
    </collision>
    <inertial>
      <mass value="13.0"/>
      <origin xyz="0 0 0"/>
      <inertia ixx="0.03" ixy="0" ixz="0" iyy="0.03" iyz="0" izz="0.03"/>
    </inertial>
  </link>
  <joint name="base_box_joint" type="fixed">
    <parent link="base_block"/>
    <child link="base_box"/>
    <origin xyz="0 0 0"/>
  </joint>
  <!-- ========= PLAQUE AVANT ========= -->
  <link name="front_plate">
    <visual>
      <geometry>
        <box size="0.9 0.4 0.04999999999999999"/>
      </geometry>
      <origin rpy="0 1.4 0" xyz="-0.05 0 0.5"/>
      <material name="bleu"/>
    </visual>
    <collision>
      <geometry>
        <box size="0.9 0.4 0.04999999999999999"/>
      </geometry>
      <origin rpy="0 1.4 0" xyz="-0.05 0 0.5"/>
    </collision>
    <inertial>
      <mass value="15.0"/>
      <origin xyz="0 0 0"/>
      <inertia ixx="0.03" ixy="0" ixz="0" iyy="0.03" iyz="0" izz="0.03"/>
    </inertial>
  </link>
  <joint name="front_plate_joint" type="fixed">
    <parent link="base_block"/>
    <child link="front_plate"/>
    <origin xyz="0 0 0"/>
  </joint>
  <link name="left_wheel">
    <visual>
      <geometry>
        <cylinder length="0.15" radius="0.162"/>
      </geometry>
      <origin rpy="1.570796 0 0" xyz="0 0 0"/>
      <material name="black"/>
    </visual>
    <collision>
      <geometry>
        <cylinder length="0.15" radius="0.162"/>
      </geometry>
      <origin rpy="1.570796 0 0" xyz="0 0 0"/>
      <surface>
        <friction>
          <ode>
            <mu>1.0</mu>
            <mu2>1.0</mu2>
          </ode>
        </friction>
      </surface>
    </collision>
    <inertial>
      <mass value="8.0"/>
      <origin xyz="0 0 0"/>
      <inertia ixx="0.01" ixy="0.0" ixz="0.0" iyy="0.01" iyz="0.0" izz="0.01"/>
    </inertial>
  </link>
  <joint name="left_wheel_joint" type="continuous">
    <parent link="base_block"/>
    <child link="left_wheel"/>
    <origin xyz="0 0.317 0"/>
    <axis xyz="0 1 0"/>
  </joint>
  <link name="right_wheel">
    <visual>
      <geometry>
        <cylinder length="0.15" radius="0.162"/>
      </geometry>
      <origin rpy="1.570796 0 0" xyz="0 0 0"/>
      <material name="black"/>
    </visual>
    <collision>
      <geometry>
        <cylinder length="0.15" radius="0.162"/>
      </geometry>
      <origin rpy="1.570796 0 0" xyz="0 0 0"/>
      <surface>
        <friction>
          <ode>
            <mu>1.0</mu>
            <mu2>1.0</mu2>
          </ode>
        </friction>
      </surface>
    </collision>
    <inertial>
      <mass value="8.0"/>
      <origin xyz="0 0 0"/>
      <inertia ixx="0.01" ixy="0.0" ixz="0.0" iyy="0.01" iyz="0.0" izz="0.01"/>
    </inertial>
  </link>
  <joint name="right_wheel_joint" type="continuous">
    <parent link="base_block"/>
    <child link="right_wheel"/>
    <origin xyz="0 -0.317 0"/>
    <axis xyz="0 1 0"/>
  </joint>
  <link name="left_caster_plate">
    <visual>
      <geometry>
        <box size="0.18 0.18 0.01"/>
      </geometry>
      <material name="grey"/>
    </visual>
    <collision>
      <geometry>
        <box size="0.18 0.18 0.01"/>
      </geometry>
    </collision>
    <inertial>
      <mass value="0.5"/>
      <origin xyz="0 0 0"/>
      <inertia ixx="0.001" ixy="0.0" ixz="0.0" iyy="0.001" iyz="0.0" izz="0.001"/>
    </inertial>
  </link>
  <joint name="left_caster_plate_joint" type="fixed">
    <parent link="base_block"/>
    <child link="left_caster_plate"/>
    <origin xyz="-0.747 0.26 0.10300000000000001"/>
    <axis xyz="0 0 1"/>
  </joint>
  <!-- petite roue -->
  <link name="left_caster_wheel">
    <visual>
      <geometry>
        <cylinder length="0.08" radius="0.13"/>
      </geometry>
      <origin rpy="1.570796 0 0" xyz="0 0 0"/>
      <material name="black"/>
    </visual>
    <collision>
      <geometry>
        <cylinder length="0.08" radius="0.13"/>
      </geometry>
      <origin rpy="1.570796 0 0" xyz="0 0 0"/>
    </collision>
    <inertial>
      <mass value="1.0"/>
      <origin xyz="0 0 0"/>
      <inertia ixx="0.0001" ixy="0.0" ixz="0.0" iyy="0.0001" iyz="0.0" izz="0.0001"/>
    </inertial>
  </link>
  <joint name="left_caster_wheel_joint" type="continuous">
    <parent link="left_caster_plate"/>
    <child link="left_caster_wheel"/>
    <origin xyz="0 0 -0.13"/>
    <axis xyz="0 1 0"/>
  </joint>
  <link name="right_caster_plate">
    <visual>
      <geometry>
        <box size="0.18 0.18 0.01"/>
      </geometry>
      <material name="grey"/>
    </visual>
    <collision>
      <geometry>
        <box size="0.18 0.18 0.01"/>
      </geometry>
    </collision>
    <inertial>
      <mass value="0.5"/>
      <origin xyz="0 0 0"/>
      <inertia ixx="0.001" ixy="0.0" ixz="0.0" iyy="0.001" iyz="0.0" izz="0.001"/>
    </inertial>
  </link>
  <joint name="right_caster_plate_joint" type="fixed">
    <parent link="base_block"/>
    <child link="right_caster_plate"/>
    <origin xyz="-0.747 -0.26 0.10300000000000001"/>
    <axis xyz="0 0 1"/>
  </joint>
  <!-- petite roue -->
  <link name="right_caster_wheel">
    <visual>
      <geometry>
        <cylinder length="0.08" radius="0.13"/>
      </geometry>
      <origin rpy="1.570796 0 0" xyz="0 0 0"/>
      <material name="black"/>
    </visual>
    <collision>
      <geometry>
        <cylinder length="0.08" radius="0.13"/>
      </geometry>
      <origin rpy="1.570796 0 0" xyz="0 0 0"/>
    </collision>
    <inertial>
      <mass value="1.0"/>
      <origin xyz="0 0 0"/>
      <inertia ixx="0.0001" ixy="0.0" ixz="0.0" iyy="0.0001" iyz="0.0" izz="0.0001"/>
    </inertial>
  </link>
  <joint name="right_caster_wheel_joint" type="continuous">
    <parent link="right_caster_plate"/>
    <child link="right_caster_wheel"/>
    <origin xyz="0 0 -0.13"/>
    <axis xyz="0 1 0"/>
  </joint>
  <link name="airy_front">
    <visual>
      <geometry>
        <cylinder length="0.06" radius="0.04"/>
      </geometry>
      <material name="red"/>
    </visual>
    <collision>
      <geometry>
        <cylinder length="0.06" radius="0.04"/>
      </geometry>
    </collision>
    <inertial>
      <mass value="0.2"/>
      <origin xyz="0 0 0"/>
      <inertia ixx="0.0002" ixy="0.0" ixz="0.0" iyy="0.0002" iyz="0.0" izz="0.0002"/>
    </inertial>
  </link>
  <joint name="airy_front_joint" type="fixed">
    <parent link="base_block"/>
    <child link="airy_front"/>
    <origin rpy="0 2.0 0" xyz="0.05 0.0 0.8"/>
  </joint>
  <link name="jt16_center">
    <visual>
      <geometry>
        <cylinder length="0.06" radius="0.04"/>
      </geometry>
      <material name="red"/>
    </visual>
    <collision>
      <geometry>
        <cylinder length="0.06" radius="0.04"/>
      </geometry>
    </collision>
    <inertial>
      <mass value="0.2"/>
      <origin xyz="0 0 0"/>
      <inertia ixx="0.0002" ixy="0.0" ixz="0.0" iyy="0.0002" iyz="0.0" izz="0.0002"/>
    </inertial>
  </link>
  <joint name="jt16_center_joint" type="fixed">
    <parent link="base_block"/>
    <child link="jt16_center"/>
    <origin rpy="0 3.14 0" xyz="-0.607 0.0 0.025"/>
  </joint>
  <link name="airy_back">
    <visual>
      <geometry>
        <cylinder length="0.06" radius="0.04"/>
      </geometry>
      <material name="red"/>
    </visual>
    <collision>
      <geometry>
        <cylinder length="0.06" radius="0.04"/>
      </geometry>
    </collision>
    <inertial>
      <mass value="0.2"/>
      <origin xyz="0 0 0"/>
      <inertia ixx="0.0002" ixy="0.0" ixz="0.0" iyy="0.0002" iyz="0.0" izz="0.0002"/>
    </inertial>
  </link>
  <joint name="airy_back_joint" type="fixed">
    <parent link="base_block"/>
    <child link="airy_back"/>
    <origin rpy="0 -1.57 0" xyz="-0.87 0.0 0.085"/>
  </joint>
</robot>
